Workbook

Sheet ใบงาน Agilent_JOB 4.1
A1: บริษัท แวตสก้า จำกัด/ Vatska Company Limited 53/2 ต. อ้อมเกร็ด อ. ปากเกร็ด จ. นนทบุรี 11120/ 53/2 T. Om-Kred A. Pakkred Nonthaburi 11120 Thailand โทร. +662 9244161 อีเมล: sales@vatska.com/ Tel: +662 9244161 E-mail: sales@vatska.com
A6: ใบงานตัดสายยางและ บรรจุ | O6: JOB 4.1
A7: วันที่ | D7: Lot No: | F7: xxx | K7: เลขที่ใบงาน RI | L7: AGA | N7: 20260803
A8: แผนก | B8: ผลิต (Production) | D8: MPN: | F8: K9801-60102 | K8: จำนวนชุดที่ต้องการ | N8: 2000
A9: ลูกค้า | B9: อาจิแลนจ์ (Agilent) | D9: Children PN: | F9: K9801-60086 | K9: Customer PO | N9: PO12345
B11: ABW00012 | C11: OD/ID: 5/16"(7.9375mm) 3/16"(4.7625mm)
B12: QR CODE
A13: วัสดุที่เบิกใช้ในการตัดสายยาง
A15: ลำดับ | B15: รายละเอียด | C15: รุ่น | D15: จำนวน/ ชุด | E15: จำนวนสายยางที่เบิกเป็นมิลลิเมตร | F15: ควายยาวสายยาง(ฟุต)ต่อกล่อง | G15: จำนวนสายยางที่เบิกเป็นมิลลิเมตร | H15: จำนวนกล่องของสายยางที่เบิกทั้งหมด
A17: 1 | B17: สายยาง | C17: ABW00012 | D17: 1 | E17: =D17*N8*(I44+J44) -> 1178400 | F17: 50 | G17: =E17 -> 1178400 | H17: =G17*0.00328/F17 -> 77.30304 | K17: Copy to sticker
A18: 2 | B18: แท่งพลาสติคเพื่อใช้ตัดสายยาง
A19: 3 | B19: กล่องพลาสติคใส่สายยางพร้อมฝาปิดกันฝุ่น | D19: 1 กล่อง
A20: 4 | B20: แผ่นยางสำหรับกำจัดฝุ่น | D20: 1 แผ่น
A21: 5 | B21: ถุงพลาสติค S | C21: 4x 6 นิ้ว | D21: =N8 -> 2000
A22: 6 | B22: สติกเกอร์ | C22: 5 x 8 ซม | D22: =N8 -> 2000
A23: 7 | B23: ไม้บรรทัดเหล็ก | C23: ขนาด 60 เซนติเมตร | D23: 1 อัน
A24: 8 | B24: ถุงพลาสติก packing
A26: การตรวจสอบคุณภาพก่อนบรรจุ / QC in process | I26: ในกรณีใช้สายยางไม่เต็มม้วน จะต้องนำไปใช้งานต่อสำหรับ JOB อื่นๆ
A28: ลำดับ | B28: รายละเอียด | C28: รุ่น | D28: จำนวน/ ชุด | E28: จำนวนที่เบิกทั้งหมด | F28: จำนวนสายยางที่ตัดได้(เส้น) | G28: ตารางเบิกสายยาง | K28: จำนวนที่ตรวจสอบความยาวของสายยาง (MM) | N28: ลายเซ็นต์
G29: วันที่ | H29: จำนวน/ม้วน | I29: Lot number ของสายยาง | J29: ลายเซ็นต์ | K29: ความยาวที่ต้องการ | L29: จำนวนที่ผ่าน | M29: จำนวนที่ไม่ผ่าน
A30: 4.1 | B30: Tubing Assembly, Waste Manifold | C30: ABW00012/K9801-60086 | D30: 1 | E30: =N8*D30 -> 2000 | F30: =N8*D30 -> 2000 | K30: 584.2-589.2
A39: การตรวจสอบคุณภาพการบรรจุ
A41: ลำดับ | B41: รายละเอียดสติกเกอร์ | C41: รายละเอียดบนสติกเกอร์ | D41: รายละเอียดบนสติกเกอร์ | F41: ขนาดถุง | G41: รุ่น | H41: จำนวนสายยาง/ ถุง | I41: ความยาวที่รับได้ | J41: ความยาวที่ต้องการ | K41: ความยาวสายยางที่สามารถยอมรับได้ | L41: จำนวนที่ตรวจสอบรายละเอียดของถุงและสติกเกอร์บนถุง | N41: จำนวนที่ตรวจสอบความยาวของสายยาง
L43: จำนวนที่ผ่าน | M43: จำนวนที่ไม่ผ่าน | N43: จำนวนที่ผ่าน | O43: จำนวนที่ไม่ผ่าน
A44: 1 | B44: K9801-60102 | C44: Tubing Assembly, Waste Manifold | D44: K9801-60086 | E44: P-06411-03 | F44: S | G44: ABW00012 | H44: 1 เส้น | I44: 584.2 | J44: +5.00 | K44: 584.2-589.2
A45: 2 | B45: K9801-60102 | D45: K9801-60102 | F45: L | H45: 5 ถุงย่อย
K49: พนักงานตรวจสอบ

Sheet ใบงาน Agilent_JOB 4.2
A1: บริษัท แวตสก้า จำกัด/ Vatska Company Limited 53/2 ต. อ้อมเกร็ด อ. ปากเกร็ด จ. นนทบุรี 11120/ 53/2 T. Om-Kred A. Pakkred Nonthaburi 11120 Thailand โทร. +662 9244161 อีเมล: sales@vatska.com/ Tel: +662 9244161 E-mail: sales@vatska.com
A6: ใบงานตัดสายยางและ บรรจุ | O6: JOB 4.2
A7: วันที่ | D7: Lot No: | F7: ='ใบงาน Agilent_JOB 4.1'!F7 -> xxx | K7: เลขที่ใบงาน RI | L7: AGA | N7: ='ใบงาน Agilent_JOB 4.1'!N7 -> 20260803
A8: แผนก | B8: ผลิต (Production) | D8: MPN: | F8: K9801-60102 | K8: จำนวนชุดที่ต้องการ | N8: ='ใบงาน Agilent_JOB 4.1'!N8 -> 2000
A9: ลูกค้า | B9: อาจิแลนจ์ (Agilent) | D9: Children PN: | F9: K9801-60087 | K9: Customer PO | N9: ='ใบงาน Agilent_JOB 4.1'!N9 -> PO12345
B11: ABW00018 | C11: OD/ID: 7/16"(11.1125mm) 1/4"(6.3500mm)
B12: QR CODE
A13: วัสดุที่เบิกใช้ในการตัดสายยาง
A15: ลำดับ | B15: รายละเอียด | C15: รุ่น | D15: จำนวน/ ชุด | E15: จำนวนสายยางที่เบิกเป็นมิลลิเมตร | F15: ควายยาวสายยาง(ฟุต)ต่อกล่อง | G15: จำนวนสายยางที่เบิกเป็นมิลลิเมตร | H15: จำนวนกล่องของสายยางที่เบิกทั้งหมด
A17: 1 | B17: สายยาง | C17: ABW00018 | D17: 2 | E17: =D17*N8*(I44+J44) -> 1544000 | F17: 50 | G17: =E17 -> 1544000 | H17: =G17*0.00328/F17 -> 101.2864 | K17: Copy to sticker
A18: 2 | B18: แท่งพลาสติคเพื่อใช้ตัดสายยาง
A19: 3 | B19: กล่องพลาสติคใส่สายยางพร้อมฝาปิดกันฝุ่น | D19: 1 กล่อง
A20: 4 | B20: แผ่นยางสำหรับกำจัดฝุ่น | D20: 1 แผ่น
A21: 5 | B21: ถุงพลาสติค M | C21: 6x9 นิ้ว | D21: =N8 -> 2000
A22: 6 | B22: สติกเกอร์ | C22: 5 x 8 ซม | D22: =N8 -> 2000
A23: 7 | B23: ไม้บรรทัดเหล็ก | C23: ขนาด 60 เซนติเมตร | D23: 1 อัน
A24: 8 | B24: ถุงพลาสติก packing
A26: การตรวจสอบคุณภาพก่อนบรรจุ / QC in process | I26: ในกรณีใช้สายยางไม่เต็มม้วน จะต้องนำไปใช้งานต่อสำหรับ JOB อื่นๆ
A28: ลำดับ | B28: รายละเอียด | C28: รุ่น | D28: จำนวน/ ชุด | E28: จำนวนที่เบิกทั้งหมด | F28: จำนวนสายยางที่ตัดได้(เส้น) | G28: ตารางเบิกสายยาง | K28: จำนวนที่ตรวจสอบความยาวของสายยาง (MM) | N28: ลายเซ็นต์
G29: วันที่ | H29: จำนวน/ม้วน | I29: Lot number ของสายยาง | J29: ลายเซ็นต์ | K29: ความยาวที่ต้องการ | L29: จำนวนที่ผ่าน | M29: จำนวนที่ไม่ผ่าน
A30: 4.2 | B30: Tubing Assembly, Waste Manifold | C30: ABW00018/K9801-60087 | D30: 2 | E30: =N8*D30 -> 4000 | F30: =N8*D30 -> 4000 | K30: 381-386
A39: การตรวจสอบคุณภาพการบรรจุ
A41: ลำดับ | B41: รายละเอียดสติกเกอร์ | C41: รายละเอียดบนสติกเกอร์ | D41: รายละเอียดบนสติกเกอร์ | F41: ขนาดถุง | G41: รุ่น | H41: จำนวนสายยาง/ ถุง | I41: ความยาวที่รับได้ | J41: ความยาวที่ต้องการ | K41: ความยาวสายยางที่สามารถยอมรับได้ | L41: จำนวนที่ตรวจสอบรายละเอียดของถุงและสติกเกอร์บนถุง | N41: จำนวนที่ตรวจสอบความยาวของสายยาง
L43: จำนวนที่ผ่าน | M43: จำนวนที่ไม่ผ่าน | N43: จำนวนที่ผ่าน | O43: จำนวนที่ไม่ผ่าน
A44: 1 | B44: K9801-60102 | C44: Tubing Assembly, Waste Manifold | D44: K9801-60087 | E44: P-95802-13 | F44: M | G44: ABW00018 | H44: 2 เส้น | I44: 381 | J44: +5.00 | K44: 381-386
A45: 2 | B45: K9801-60102 | D45: K9801-60102 | F45: L | H45: 5 ถุงย่อย
K49: พนักงานตรวจสอบ

Sheet ใบงาน Agilent_JOB 4.3
A1: บริษัท แวตสก้า จำกัด/ Vatska Company Limited 53/2 ต. อ้อมเกร็ด อ. ปากเกร็ด จ. นนทบุรี 11120/ 53/2 T. Om-Kred A. Pakkred Nonthaburi 11120 Thailand โทร. +662 9244161 อีเมล: sales@vatska.com/ Tel: +662 9244161 E-mail: sales@vatska.com
A6: ใบงานตัดสายยางและ บรรจุ | O6: JOB 4.3
A7: วันที่ | D7: Lot No: | F7: ='ใบงาน Agilent_JOB 4.1'!F7 -> xxx | K7: เลขที่ใบงาน RI | L7: AGA | N7: ='ใบงาน Agilent_JOB 4.1'!N7 -> 20260803
A8: แผนก | B8: ผลิต (Production) | D8: MPN: | F8: K9801-60102 | K8: จำนวนชุดที่ต้องการ | N8: 2000
A9: ลูกค้า | B9: อาจิแลนจ์ (Agilent) | D9: Children PN: | F9: K9801-60088 | K9: Customer PO | N9: ='ใบงาน Agilent_JOB 4.1'!N9 -> PO12345
B11: ABW00018 | C11: OD/ID: 7/16"(11.1125mm) 1/4"(6.3500mm)
B12: QR CODE
A13: วัสดุที่เบิกใช้ในการตัดสายยาง
A15: ลำดับ | B15: รายละเอียด | C15: รุ่น | D15: จำนวน/ ชุด | E15: จำนวนสายยางที่เบิกเป็นมิลลิเมตร | F15: ควายยาวสายยาง(ฟุต)ต่อกล่อง | G15: จำนวนสายยางที่เบิกเป็นมิลลิเมตร | H15: จำนวนกล่องของสายยางที่เบิกทั้งหมด
A17: 1 | B17: สายยาง | C17: ABW00018 | D17: 2 | E17: =D17*N8*(I44+J44) -> 1340800 | F17: 50 | G17: =E17 -> 1340800 | H17: =G17*0.00328/F17 -> 87.95648 | K17: Copy to sticker
A18: 2 | B18: แท่งพลาสติคเพื่อใช้ตัดสายยาง
A19: 3 | B19: กล่องพลาสติคใส่สายยางพร้อมฝาปิดกันฝุ่น | D19: 1 กล่อง
A20: 4 | B20: แผ่นยางสำหรับกำจัดฝุ่น | D20: 1 แผ่น
A21: 5 | B21: ถุงพลาสติค M | C21: 6x9 นิ้ว | D21: =N8 -> 2000
A22: 6 | B22: สติกเกอร์ | C22: 5 x 8 ซม | D22: =N8 -> 2000
A23: 7 | B23: ไม้บรรทัดเหล็ก | C23: ขนาด 60 เซนติเมตร | D23: 1 อัน
A24: 8 | B24: ถุงพลาสติก packing
A26: วัสดุที่เบิกใช้ในการบรรจุและการตรวจสอบคุณภาพก่อนบรรจุ / QC in process
A28: ลำดับ | B28: รายละเอียด | C28: รุ่น | D28: จำนวน/ ชุด | E28: จำนวนที่เบิกทั้งหมด | F28: จำนวนสายยางที่ตัดได้(เส้น) | G28: ตารางเบิกสายยาง | K28: จำนวนที่ตรวจสอบความยาวของสายยาง (MM) | N28: ลายเซ็นต์
G29: วันที่ | H29: จำนวน/ม้วน | I29: Lot number ของสายยาง | J29: ลายเซ็นต์ | K29: ความยาวที่ต้องการ | L29: จำนวนที่ผ่าน | M29: จำนวนที่ไม่ผ่าน
A30: 4.3 | B30: Tubing Assembly, Waste Manifold | C30: ABW00018/K9801-60088 | D30: 2 | E30: =N8*D30 -> 4000 | F30: =N8*D30 -> 4000 | K30: 330.2-335.2
A39: การตรวจสอบคุณภาพการบรรจุ
A41: ลำดับ | B41: รายละเอียดสติกเกอร์ | C41: รายละเอียดบนสติกเกอร์ | D41: รายละเอียดบนสติกเกอร์ | F41: ขนาดถุง | G41: รุ่น | H41: จำนวนสายยาง/ ถุง | I41: ความยาวที่รับได้ | J41: ความยาวที่ต้องการ | K41: ความยาวสายยางที่สามารถยอมรับได้ | L41: จำนวนที่ตรวจสอบรายละเอียดของถุงและสติกเกอร์บนถุง | N41: จำนวนที่ตรวจสอบความยาวของสายยาง
L43: จำนวนที่ผ่าน | M43: จำนวนที่ไม่ผ่าน | N43: จำนวนที่ผ่าน | O43: จำนวนที่ไม่ผ่าน
A44: 1 | B44: K9801-60102 | C44: Tubing Assembly, Waste Manifold | D44: K9801-60088 | E44: P-95802-13 | F44: M | G44: ABW00018 | H44: 2 เส้น | I44: 330.2 | J44: +5.00 | K44: 330.2-335.2
A45: 2 | B45: K9801-60102 | D45: K9801-60102 | F45: L | H45: 5 ถุงย่อย
K49: พนักงานตรวจสอบ

Sheet ใบงาน Agilent_JOB 4.4
A1: บริษัท แวตสก้า จำกัด/ Vatska Company Limited 53/2 ต. อ้อมเกร็ด อ. ปากเกร็ด จ. นนทบุรี 11120/ 53/2 T. Om-Kred A. Pakkred Nonthaburi 11120 Thailand โทร. +662 9244161 อีเมล: sales@vatska.com/ Tel: +662 9244161 E-mail: sales@vatska.com
A6: ใบงานตัดสายยางและ บรรจุ | O6: JOB 4.4
A7: วันที่ | D7: Lot No: | F7: ='ใบงาน Agilent_JOB 4.1'!F7 -> xxx | K7: เลขที่ใบงาน RI | L7: AGA | N7: ='ใบงาน Agilent_JOB 4.1'!N7 -> 20260803
A8: แผนก | B8: ผลิต (Production) | D8: MPN: | F8: K9801-60102 | K8: จำนวนชุดที่ต้องการ | N8: 2000
A9: ลูกค้า | B9: อาจิแลนจ์ (Agilent) | D9: Children PN: | F9: K9801-60089 | K9: Customer PO | N9: ='ใบงาน Agilent_JOB 4.1'!N9 -> PO12345
B11: ABW00018 | C11: OD/ID: 7/16"(11.1125mm) 1/4"(6.3500mm)
B12: QR CODE
A13: วัสดุที่เบิกใช้ในการตัดสายยาง
A15: ลำดับ | B15: รายละเอียด | C15: รุ่น | D15: จำนวน/ ชุด | E15: จำนวนสายยางที่เบิกเป็นมิลลิเมตร | F15: ควายยาวสายยาง(ฟุต)ต่อกล่อง | G15: จำนวนสายยางที่เบิกเป็นมิลลิเมตร | H15: จำนวนกล่องของสายยางที่เบิกทั้งหมด
A17: 1 | B17: สายยาง | C17: ABW00018 | D17: 2 | E17: =D17*N8*(I44+J44) -> 934400 | F17: 50 | G17: =E17 -> 934400 | H17: =G17*0.00328/F17 -> 61.29664 | K17: Copy to sticker
A18: 2 | B18: แท่งพลาสติคเพื่อใช้ตัดสายยาง
A19: 3 | B19: กล่องพลาสติคใส่สายยางพร้อมฝาปิดกันฝุ่น | D19: 1 กล่อง
A20: 4 | B20: แผ่นยางสำหรับกำจัดฝุ่น | D20: 1 แผ่น
A21: 5 | B21: ถุงพลาสติค M | C21: 6x9 นิ้ว | D21: =N8 -> 2000
A22: 6 | B22: สติกเกอร์ | C22: 5 x 8 ซม | D22: =N8 -> 2000
A23: 7 | B23: ไม้บรรทัดเหล็ก | C23: ขนาด 60 เซนติเมตร | D23: 1 อัน
A24: 8 | B24: ถุงพลาสติก packing
A26: การตรวจสอบคุณภาพก่อนบรรจุ / QC in process | I26: ในกรณีใช้สายยางไม่เต็มม้วน จะต้องนำไปใช้งานต่อสำหรับ JOB อื่นๆ
A28: ลำดับ | B28: รายละเอียด | C28: รุ่น | D28: จำนวน/ ชุด | E28: จำนวนที่เบิกทั้งหมด | F28: จำนวนสายยางที่ตัดได้(เส้น) | G28: ตารางเบิกสายยาง | K28: จำนวนที่ตรวจสอบความยาวของสายยาง (MM) | N28: ลายเซ็นต์
G29: วันที่ | H29: จำนวน/ม้วน | I29: Lot number ของสายยาง | J29: ลายเซ็นต์ | K29: ความยาวที่ต้องการ | L29: จำนวนที่ผ่าน | M29: จำนวนที่ไม่ผ่าน
A30: 4.4 | B30: Tubing Assembly, Waste Manifold | C30: ABW00018/K9801-60089 | D30: 2 | E30: =N8*D30 -> 4000 | F30: =N8*D30 -> 4000 | K30: 228.6-233.6
A39: การตรวจสอบคุณภาพการบรรจุ
A41: ลำดับ | B41: รายละเอียดสติกเกอร์ | C41: รายละเอียดบนสติกเกอร์ | D41: รายละเอียดบนสติกเกอร์ | F41: ขนาดถุง | G41: รุ่น | H41: จำนวนสายยาง/ ถุง | I41: ความยาวที่รับได้ | J41: ความยาวที่ต้องการ | K41: ความยาวสายยางที่สามารถยอมรับได้ | L41: จำนวนที่ตรวจสอบรายละเอียดของถุงและสติกเกอร์บนถุง | N41: จำนวนที่ตรวจสอบความยาวของสายยาง
L43: จำนวนที่ผ่าน | M43: จำนวนที่ไม่ผ่าน | N43: จำนวนที่ผ่าน | O43: จำนวนที่ไม่ผ่าน
A44: 1 | B44: K9801-60102 | C44: Tubing Assembly, Waste Manifold | D44: K9801-60089 | E44: P-95802-13 | F44: M | G44: ABW00018 | H44: 2 เส้น | I44: 228.6 | J44: +5.00 | K44: 228.6-233.6
A45: 2 | B45: K9801-60102 | D45: K9801-60102 | F45: L | H45: 5 ถุงย่อย
K49: พนักงานตรวจสอบ

Sheet ใบงาน Agilent_JOB 4.5
A1: บริษัท แวตสก้า จำกัด/ Vatska Company Limited 53/2 ต. อ้อมเกร็ด อ. ปากเกร็ด จ. นนทบุรี 11120/ 53/2 T. Om-Kred A. Pakkred Nonthaburi 11120 Thailand โทร. +662 9244161 อีเมล: sales@vatska.com/ Tel: +662 9244161 E-mail: sales@vatska.com
A6: ใบงานตัดสายยางและ บรรจุ | O6: JOB 4.5
A7: วันที่ | D7: Lot No: | F7: ='ใบงาน Agilent_JOB 4.1'!F7 -> xxx | K7: เลขที่ใบงาน RI | L7: AGA | N7: ='ใบงาน Agilent_JOB 4.1'!N7 -> 20260803
A8: แผนก | B8: ผลิต (Production) | D8: MPN: | F8: K9801-60102 | K8: จำนวนชุดที่ต้องการ | N8: 2000
A9: ลูกค้า | B9: อาจิแลนจ์ (Agilent) | D9: Children PN: | F9: K9801-60090 | K9: Customer PO | N9: ='ใบงาน Agilent_JOB 4.1'!N9 -> PO12345
B11: ABW00018 | C11: OD/ID: 7/16"(11.1125mm) 1/4"(6.3500mm)
B12: QR CODE
A13: วัสดุที่เบิกใช้ในการตัดสายยาง
A15: ลำดับ | B15: รายละเอียด | C15: รุ่น | D15: จำนวน/ ชุด | E15: จำนวนสายยางที่เบิกเป็นมิลลิเมตร | F15: ควายยาวสายยาง(ฟุต)ต่อกล่อง | G15: จำนวนสายยางที่เบิกเป็นมิลลิเมตร | H15: จำนวนกล่องของสายยางที่เบิกทั้งหมด
A17: 1 | B17: สายยาง | C17: ABW00018 | D17: 2 | E17: =D17*N8*(I44+J44) -> 832800 | F17: 50 | G17: =E17 -> 832800 | H17: =G17*0.00328/F17 -> 54.63168 | K17: Copy to sticker
A18: 2 | B18: แท่งพลาสติคเพื่อใช้ตัดสายยาง
A19: 3 | B19: กล่องพลาสติคใส่สายยางพร้อมฝาปิดกันฝุ่น | D19: 1 กล่อง
A20: 4 | B20: แผ่นยางสำหรับกำจัดฝุ่น | D20: 1 แผ่น
A21: 5 | B21: ถุงพลาสติค M | C21: 6x9 นิ้ว | D21: =N8 -> 2000
A22: 6 | B22: สติกเกอร์ | C22: 5 x 8 ซม | D22: =N8 -> 2000
A23: 7 | B23: ไม้บรรทัดเหล็ก | C23: ขนาด 60 เซนติเมตร | D23: 1 อัน
A24: 8 | B24: ถุงพลาสติก packing
A26: การตรวจสอบคุณภาพก่อนบรรจุ / QC in process | I26: ในกรณีใช้สายยางไม่เต็มม้วน จะต้องนำไปใช้งานต่อสำหรับ JOB อื่นๆ
A28: ลำดับ | B28: รายละเอียด | C28: รุ่น | D28: จำนวน/ ชุด | E28: จำนวนที่เบิกทั้งหมด | F28: จำนวนสายยางที่ตัดได้(เส้น) | G28: ตารางเบิกสายยาง | K28: จำนวนที่ตรวจสอบความยาวของสายยาง (MM) | N28: ลายเซ็นต์
G29: วันที่ | H29: จำนวน/ม้วน | I29: Lot number ของสายยาง | J29: ลายเซ็นต์ | K29: ความยาวที่ต้องการ | L29: จำนวนที่ผ่าน | M29: จำนวนที่ไม่ผ่าน
A30: 4.5 | B30: Tubing Assembly, Waste Manifold | C30: ABW00018/K9801-60090 | D30: 2 | E30: =N8*D30 -> 4000 | F30: =N8*D30 -> 4000 | K30: 203.2-208.2
A39: การตรวจสอบคุณภาพการบรรจุ
A41: ลำดับ | B41: รายละเอียดสติกเกอร์ | C41: รายละเอียดบนสติกเกอร์ | D41: รายละเอียดบนสติกเกอร์ | F41: ขนาดถุง | G41: รุ่น | H41: จำนวนสายยาง/ ถุง | I41: ความยาวที่รับได้ | J41: ความยาวที่ต้องการ | K41: ความยาวสายยางที่สามารถยอมรับได้ | L41: จำนวนที่ตรวจสอบรายละเอียดของถุงและสติกเกอร์บนถุง | N41: จำนวนที่ตรวจสอบความยาวของสายยาง
L43: จำนวนที่ผ่าน | M43: จำนวนที่ไม่ผ่าน | N43: จำนวนที่ผ่าน | O43: จำนวนที่ไม่ผ่าน
A44: 1 | B44: K9801-60102 | C44: Tubing Assembly, Waste Manifold | D44: K9801-60090 | E44: P-95802-13 | F44: M | G44: ABW00018 | H44: 2 เส้น | I44: 203.2 | J44: +5.00 | K44: 203.2-208.2
A45: 2 | B45: K9801-60102 | D45: K9801-60102 | F45: L | H45: 5 ถุงย่อย
K49: พนักงานตรวจสอบ

Sheet A2-QC ถุง
A1: บริษัท แวตสก้า จำกัด/ Vatska Company Limited 53/2 ต. อ้อมเกร็ด อ. ปากเกร็ด จ. นนทบุรี 11120/ 53/2 T. Om-Kred A. Pakkred Nonthaburi 11120 Thailand โทร. +662 9244161 อีเมล: sales@vatska.com/ Tel: +662 9244161 E-mail: sales@vatska.com
A6: เอกสารตรวจสอบผลิตภัณฑ์ QC (Quality Control)
A7: เอกสารตรวจสอบผลิตภัณฑ์ QC (Quality Control) | C7: Lot no | G7: ='ใบงาน Agilent_JOB 4.1'!F7 -> xxx | S7: เลขที่ใบงาน RI | X7: ='ใบงาน Agilent_JOB 4.1'!N7 -> 20260803
A8: MPN | B8: ='ใบงาน Agilent_JOB 4.1'!F8 -> K9801-60102 | C8: Children no. | G8: ='ใบงาน Agilent_JOB 4.1'!F9 -> K9801-60086
G9: ='ใบงาน Agilent_JOB 4.2'!F9 -> K9801-60087 | S9: Copy to sticker
A10: จำนวนถุงที่ผลิต | B10: ='ใบงาน Agilent_JOB 4.1'!N8 -> 2000 | G10: ='ใบงาน Agilent_JOB 4.3'!F9 -> K9801-60088
G11: ='ใบงาน Agilent_JOB 4.4'!F9 -> K9801-60089
A12: QR CODE | G12: ='ใบงาน Agilent_JOB 4.5'!F9 -> K9801-60090
A14: ลำดับ | B14: รายการการตรวจสอบ | C14: จำนวนที่สุ่ม ( เส้น/ถุง) | I14: จำนวนที่ผ่าน | O14: จำนวนที่ไม่ผ่าน | U14: ลายเซ็นต์ผู้ตรวจสอบ
A16: 1 | B16: ความถูกต้องของความยาวของสายยางว่าอยู่ภายในระยะที่กำหนด (ตามรายละเอียดแนบ) | I16: ฤฉ
A17: 2 | B17: สติกเกอร์ (Label)
B18: ความถูกต้องของรหัสสินค้า (Part Number)
B19: ความถูกต้องของขนาดสายยาง (MPN)
B20: ความถูกต้องของวันเดือนปีที่ผลิต (DOM)
B21: ความถูกต้องของจำนวน / ถุง (QTY)
A22: 3 | B22: ความสวยงานของการแพ็ค เช่น การซีลถุง
A23: 4 | B23: ความสะอาดความสายยางภายในถุง
A24: 5 | B24: ความสะอาดของถุงโดยรวม
A25: 6 | B25: เมื่อ scan barcode ข้อมูลถูกต้อง
A27: จำนวนกลุ่มตัวอย่างที่สุ่ม QC
A28: สุ่มตรวจ 10 % ของจำนวนสายยาง | C28: จำนวนสุ่มสายยาง QC | G28: จำนวนสุ่มถุงบรรจุ QC
A29: จำนวนตัวอย่างสุ่ม 1-100 | C29: 10 | G29: 10
A30: จำนวนตัวอย่างสุ่ม 100-200 | C30: 20 | G30: 20
A31: จำนวนตัวอย่างสุ่ม 200-300 | C31: 30 | G31: 30
A32: จำนวนตัวอย่างสุ่ม 300-400 | C32: 40 | G32: 40
A33: จำนวนตัวอย่างสุ่ม 400-500 | C33: 50 | G33: 50
A34: จำนวนตัวอย่างสุ่ม 500-1000 | C34: 100 | G34: 100
A35: จำนวนตัวอย่างสุ่ม 1000-2000 | C35: 200 | G35: 200
A36: จำนวนตัวอย่างสุ่มมากว่า 1000 | C36: คิดเป็น 10% ของจำนวนทั้งหมด
A42: รายการ | B42: JOB NUMBER | C42: เกณฑ์ระยะความยาวของสายยางที่ยอมรับได้ | O42: Model | T42: Part number | X42: QTY/ bag
A43: 1 K9801-60098 | B43: job 1.1 | C43: 152.4 -157.4 | O43: ABW00007 | T43: K9801-60079 | X43: 1
B44: job 1.2 | C44: 558.8 -563.8 | O44: ABW00007 | T44: K9801-60080 | X44: 1
B45: job 1.3 | C45: 57.15 -58.15 | O45: ABW00017 | T45: K9801-60081 | X45: 6
B46: job 1.4 | C46: 107 -108 | O46: ABW00002 | T46: K9801-60084 | X46: 6
B47: job 1.5 | C47: 762 -767 | O47: ABW00002 | T47: K9801-60085 | X47: 6
A48: 2 K9801-60099 | B48: job 2.1 | C48: 55.34 -55.84 | O48: ABW00019 | T48: K9801-60082 | X48: 2
B49: job 2.2 | C49: 119.82 -120.82 | O49: STHT-C-125-4F | T49: K9801-60083 | X49: 1
A50: 3 K9801-60100 | B50: job 3.1 | C50: 254 -259 | O50: ABW00018 | T50: K9801-60092 | X50: 1
B51: job 3.2 | C51: 44.45 -45.45 | O51: ABW00018 | T51: K9801-60093 | X51: 4
B52: job 3.3 | C52: 349.25 -354.25 | O52: ABW00007 | T52: K9801-60095 | X52: 1
...

Sheet P2--QCกล่อง
A1: บริษัท แวตสก้า จำกัด/ Vatska Company Limited 53/2 ต. อ้อมเกร็ด อ. ปากเกร็ด จ. นนทบุรี 11120/ 53/2 T. Om-Kred A. Pakkred Nonthaburi 11120 Thailand โทร. +662 9244161 อีเมล: sales@vatska.com/ Tel: +662 9244161 E-mail: sales@vatska.com
A6: เอกสารตรวจสอบผลิตภัณฑ์ QC (Quality Control) สำหรับบรรจุ
A7: เอกสารตรวจสอบผลิตภัณฑ์ QC (Quality Control) สำหรับบรรจุ | C7: Lot no | G7: ='ใบงาน Agilent_JOB 4.1'!F7 -> xxx | S7: เลขที่ใบงาน RI | W7: ='ใบงาน Agilent_JOB 4.1'!N7 -> 20260803
A8: MPN | B8: ='ใบงาน Agilent_JOB 4.1'!F8 -> K9801-60102 | C8: Children no. | G8: ='ใบงาน Agilent_JOB 4.1'!F9 -> K9801-60086 | S8: CUSTOMER PO | W8: ='ใบงาน Agilent_JOB 4.1'!N9 -> PO12345
A9: จำนวนกล่อง | B9: ='ใบงาน Agilent_JOB 4.1'!N8/50 -> 40 | G9: ='ใบงาน Agilent_JOB 4.2'!F9 -> K9801-60087 | S9: Copy to sticker
G10: ='ใบงาน Agilent_JOB 4.3'!F9 -> K9801-60088
G11: ='ใบงาน Agilent_JOB 4.4'!F9 -> K9801-60089
G12: ='ใบงาน Agilent_JOB 4.5'!F9 -> K9801-60090
A15: BAR CODE
A17: ลำดับ | B17: รายการการตรวจสอบ | C17: จำนวนที่สุ่ม ( เส้น/ถุง) | I17: จำนวนที่ผ่าน | O17: จำนวนที่ไม่ผ่าน | U17: ลายเซ็นต์ผู้ตรวจสอบ
A19: 1 | B19: สติกเกอร์ (Label)
B20: ความถูกต้องของรหัสสินค้า (Part Number)
B21: ความถูกต้องของขนาดสายยาง (MPN)
B22: ความถูกต้องของวันเดือนปีที่ผลิต (DOM)
B23: ความถูกต้องของจำนวน / ถุง (QTY)
A24: 2 | B24: ความสวยงานของการแพ็ค เช่น การซีลถุง
A25: 3 | B25: ความสะอาดความสายยางภายในกล่อง
A26: 4 | B26: เมื่อ scan QR code ข้อมูลถูกต้อง
